Workbook
Name Slicer_Diabetes_Status: #N/A
Name Slicer_Weight_Status: #N/A

Sheet Customer Names
A1: Customer ID | B1: Title | C1: First Name | D1: Last Name
A2: Id1 | B2: Hawks | C2: Ms.Kelly
A3: Id2 | B3: Lehner | C3: Mr.Matthew | D3: D
A4: Id3 | B4: Lu | C4: Mr.Phil | F4: Question No:2
A5: Id4 | B5: Osborne | C5: Ms.Kelsey
A6: Id5 | B6: Kadala | C6: Ms.Kristyn | F6: DATA TRANSFORMATION
A7: Id6 | B7: Baker | C7: Mr.Russell | D7: B
A8: Id7 | B8: Macpherson | C8: Mr.Scott | F8: 1.Split the Columns in Customer Names
A9: Id8 | B9: Hallman | C9: Mr.Stephen
A10: Id9 | B10: Moran | C10: Mr.Patrick | D10: R | F10: Using Text to Column Delimiter to separate the three columns
A11: Id10 | B11: Benner | C11: Ms.Brooke | D11: N
A12: Id11 | B12: Fierro Vargas | C12: Ms.Paola | D12: Andrea
A13: Id12 | B13: Franz | C13: Mr.David
A14: Id13 | B14: Foster | C14: Mr.Wade
A15: Id14 | B15: Tenorio | C15: Mr.Franklin
A16: Id15 | B16: Rios | C16: Ms.Leilani | D16: M
A17: Id16 | B17: Viau-Dupuis | C17: Mr.Philippe
A18: Id17 | B18: Cronin | C18: Ms.Jennifer | D18: A
A19: Id18 | B19: Noordstar | C19: Ms.Christina | D19: M
A20: Id19 | B20: Boudalia | C20: Mr.Said | D20: Sr
A21: Id20 | B21: Flor | C21: Mr.John
A22: Id21 | B22: Fennon | C22: Mr.Myles
A23: Id22 | B23: Hribar | C23: Ms.Madelyn | D23: C
A24: Id23 | B24: Tassello | C24: Ms.Nicole
A25: Id24 | B25: Mauricette | C25: Mr.Eric | D25: A
A26: Id25 | B26: Garcia | C26: Mr.Emiliano | D26: I
A27: Id26 | B27: Airoldi | C27: Mr.Adam
A28: Id27 | B28: Cater-Cyker | C28: Mr.Zach
A29: Id28 | B29: Hamm | C29: Ms.Stephanie | D29: W
A30: Id29 | B30: Cox | C30: Mr.Stephen
A31: Id30 | B31: Sachrajda | C31: Ms.Natalie
A32: Id31 | B32: Gareri | C32: Ms.Nicole | D32: J
A33: Id32 | B33: Welch | C33: Mr.Jefferson | D33: D
A34: Id33 | B34: Prindiville | C34: Mr.Brendan | D34: D
A35: Id34 | B35: Kincaid | C35: Ms.Courtney
A36: Id35 | B36: Bruestle | C36: Ms.Sydney | D36: L
A37: Id36 | B37: Lachance | C37: Mr.Julien
A38: Id37 | B38: Eason | C38: Mr.Ryan | D38: M
A39: Id38 | B39: Grummon | C39: Ms.Anna | D39: H
A40: Id39 | B40: Vanwechel | C40: Ms.Samantha
...

Sheet Data Cleaning in Medical Examin
A1: Customer ID | B1: BMI | C1: Weight Status | D1: HBA1C | E1: Diabetes Status | F1: Heart Issues | G1: Any Transplants | H1: Cancer History | I1: Number of Major Surgeries | J1: Smoker | K1: Smoker
A2: Id1 | B2: 47.41 | C2: =IF(B2<18.5,"Under Weight",IF(B2<25,"Normal Weight",IF(B2<30,"Over Weight","Obesity"))) -> Obesity | D2: 7.47 | E2: =IF(D2<5.7,"Normal",IF(D2<6.4,"Prediabetes","Diabetes")) -> Diabetes | F2: No | G2: No | H2: No | I2: No Major Surgery | J2: Yes | K2: =IF(J2="?","No",J2) -> Yes
A3: Id2 | B3: 30.36 | C3: =IF(B3<18.5,"Under Weight",IF(B3<25,"Normal Weight",IF(B3<30,"Over Weight","Obesity"))) -> Obesity | D3: 5.77 | E3: =IF(D3<5.7,"Normal",IF(D3<6.4,"Prediabetes","Diabetes")) -> Prediabetes | F3: No | G3: No | H3: No | I3: No Major Surgery | J3: Yes | K3: =IF(J3="?","No",J3) -> Yes
A4: Id3 | B4: 34.485 | C4: =IF(B4<18.5,"Under Weight",IF(B4<25,"Normal Weight",IF(B4<30,"Over Weight","Obesity"))) -> Obesity | D4: 11.87 | E4: =IF(D4<5.7,"Normal",IF(D4<6.4,"Prediabetes","Diabetes")) -> Diabetes | F4: Yes | G4: No | H4: No | I4: 2 Major Surgery | J4: Yes | K4: =IF(J4="?","No",J4) -> Yes | N4: Question No:1 | Q4: Question No:2
A5: Id4 | B5: 38.095 | C5: =IF(B5<18.5,"Under Weight",IF(B5<25,"Normal Weight",IF(B5<30,"Over Weight","Obesity"))) -> Obesity | D5: 6.05 | E5: =IF(D5<5.7,"Normal",IF(D5<6.4,"Prediabetes","Diabetes")) -> Prediabetes | F5: No | G5: No | H5: No | I5: No Major Surgery | J5: Yes | K5: =IF(J5="?","No",J5) -> Yes
A6: Id5 | B6: 35.53 | C6: =IF(B6<18.5,"Under Weight",IF(B6<25,"Normal Weight",IF(B6<30,"Over Weight","Obesity"))) -> Obesity | D6: 5.45 | E6: =IF(D6<5.7,"Normal",IF(D6<6.4,"Prediabetes","Diabetes")) -> Normal | F6: No | G6: No | H6: No | I6: No Major Surgery | J6: Yes | K6: =IF(J6="?","No",J6) -> Yes | N6: DATA CLEANING | Q6: DATA TRANSFORMATION
A7: Id6 | B7: 32.8 | C7: =IF(B7<18.5,"Under Weight",IF(B7<25,"Normal Weight",IF(B7<30,"Over Weight","Obesity"))) -> Obesity | D7: 6.59 | E7: =IF(D7<5.7,"Normal",IF(D7<6.4,"Prediabetes","Diabetes")) -> Diabetes | F7: No | G7: No | H7: No | I7: No Major Surgery | J7: Yes | K7: =IF(J7="?","No",J7) -> Yes
A8: Id7 | B8: 36.4 | C8: =IF(B8<18.5,"Under Weight",IF(B8<25,"Normal Weight",IF(B8<30,"Over Weight","Obesity"))) -> Obesity | D8: 6.07 | E8: =IF(D8<5.7,"Normal",IF(D8<6.4,"Prediabetes","Diabetes")) -> Prediabetes | F8: No | G8: No | H8: No | I8: No Major Surgery | J8: Yes | K8: =IF(J8="?","No",J8) -> Yes | N8: 1.Check the no of Missing Values in Medical Examinations | Q8: 4.Weight Status
A9: Id8 | B9: 36.96 | C9: =IF(B9<18.5,"Under Weight",IF(B9<25,"Normal Weight",IF(B9<30,"Over Weight","Obesity"))) -> Obesity | D9: 7.93 | E9: =IF(D9<5.7,"Normal",IF(D9<6.4,"Prediabetes","Diabetes")) -> Diabetes | F9: No | G9: No | H9: No | I9: 3 Major Surgery | J9: Yes | K9: =IF(J9="?","No",J9) -> Yes
A10: Id9 | B10: 41.14 | C10: =IF(B10<18.5,"Under Weight",IF(B10<25,"Normal Weight",IF(B10<30,"Over Weight","Obesity"))) -> Obesity | D10: 9.58 | E10: =IF(D10<5.7,"Normal",IF(D10<6.4,"Prediabetes","Diabetes")) -> Diabetes | F10: Yes | G10: No | H10: Yes | I10: 1 Major Surgery | J10: Yes | K10: =IF(J10="?","No",J10) -> Yes | N10: Using Countif Function | Q10: Using If Function
A11: Id10 | B11: 38.06 | C11: =IF(B11<18.5,"Under Weight",IF(B11<25,"Normal Weight",IF(B11<30,"Over Weight","Obesity"))) -> Obesity | D11: 10.79 | E11: =IF(D11<5.7,"Normal",IF(D11<6.4,"Prediabetes","Diabetes")) -> Diabetes | F11: No | G11: No | H11: No | I11: No Major Surgery | J11: Yes | K11: =IF(J11="?","No",J11) -> Yes | N11: I find that 2 missing Values in Smoker Column and another columns are no missing values | Q11: IF(B2<18.5,"Under Weight",IF(B2<25,"Normal Weight",IF(B2<30,"Over weight","Obesity")))
A12: Id11 | B12: 37.7 | C12: =IF(B12<18.5,"Under Weight",IF(B12<25,"Normal Weight",IF(B12<30,"Over Weight","Obesity"))) -> Obesity | D12: 5.96 | E12: =IF(D12<5.7,"Normal",IF(D12<6.4,"Prediabetes","Diabetes")) -> Prediabetes | F12: Yes | G12: No | H12: No | I12: 2 Major Surgery | J12: Yes | K12: =IF(J12="?","No",J12) -> Yes
A13: Id12 | B13: 42.13 | C13: =IF(B13<18.5,"Under Weight",IF(B13<25,"Normal Weight",IF(B13<30,"Over Weight","Obesity"))) -> Obesity | D13: 11.9 | E13: =IF(D13<5.7,"Normal",IF(D13<6.4,"Prediabetes","Diabetes")) -> Diabetes | F13: No | G13: No | H13: No | I13: No Major Surgery | J13: Yes | K13: =IF(J13="?","No",J13) -> Yes | N13: COUNTIF(H2:H2336,"?")
A14: Id13 | B14: 40.92 | C14: =IF(B14<18.5,"Under Weight",IF(B14<25,"Normal Weight",IF(B14<30,"Over Weight","Obesity"))) -> Obesity | D14: 8.41 | E14: =IF(D14<5.7,"Normal",IF(D14<6.4,"Prediabetes","Diabetes")) -> Diabetes | F14: No | G14: No | H14: No | I14: No Major Surgery | J14: Yes | K14: =IF(J14="?","No",J14) -> Yes | N14: =COUNTIF(J3:J2337,"?") -> 2
A15: Id14 | B15: 40.565 | C15: =IF(B15<18.5,"Under Weight",IF(B15<25,"Normal Weight",IF(B15<30,"Over Weight","Obesity"))) -> Obesity | D15: 7.02 | E15: =IF(D15<5.7,"Normal",IF(D15<6.4,"Prediabetes","Diabetes")) -> Diabetes | F15: No | G15: No | H15: No | I15: No Major Surgery | J15: Yes | K15: =IF(J15="?","No",J15) -> Yes
A16: Id15 | B16: 36.385 | C16: =IF(B16<18.5,"Under Weight",IF(B16<25,"Normal Weight",IF(B16<30,"Over Weight","Obesity"))) -> Obesity | D16: 7.59 | E16: =IF(D16<5.7,"Normal",IF(D16<6.4,"Prediabetes","Diabetes")) -> Diabetes | F16: Yes | G16: No | H16: No | I16: 2 Major Surgery | J16: Yes | K16: =IF(J16="?","No",J16) -> Yes
A17: Id16 | B17: 39.9 | C17: =IF(B17<18.5,"Under Weight",IF(B17<25,"Normal Weight",IF(B17<30,"Over Weight","Obesity"))) -> Obesity | D17: 11.32 | E17: =IF(D17<5.7,"Normal",IF(D17<6.4,"Prediabetes","Diabetes")) -> Diabetes | F17: No | G17: No | H17: No | I17: No Major Surgery | J17: Yes | K17: =IF(J17="?","No",J17) -> Yes | N17: 3.Frequently Occuring Values in Smoker Column
A18: Id17 | B18: 33.8 | C18: =IF(B18<18.5,"Under Weight",IF(B18<25,"Normal Weight",IF(B18<30,"Over Weight","Obesity"))) -> Obesity | D18: 7.67 | E18: =IF(D18<5.7,"Normal",IF(D18<6.4,"Prediabetes","Diabetes")) -> Diabetes | F18: No | G18: No | H18: No | I18: 3 Major Surgery | J18: Yes | K18: =IF(J18="?","No",J18) -> Yes
A19: Id18 | B19: 36.765 | C19: =IF(B19<18.5,"Under Weight",IF(B19<25,"Normal Weight",IF(B19<30,"Over Weight","Obesity"))) -> Obesity | D19: 7.29 | E19: =IF(D19<5.7,"Normal",IF(D19<6.4,"Prediabetes","Diabetes")) -> Diabetes | F19: Yes | G19: No | H19: Yes | I19: 1 Major Surgery | J19: Yes | K19: =IF(J19="?","No",J19) -> Yes | N19: I find that No Smokers are frequently occuring this column
A20: Id19 | B20: 36.955 | C20: =IF(B20<18.5,"Under Weight",IF(B20<25,"Normal Weight",IF(B20<30,"Over Weight","Obesity"))) -> Obesity | D20: 4.72 | E20: =IF(D20<5.7,"Normal",IF(D20<6.4,"Prediabetes","Diabetes")) -> Normal | F20: Yes | G20: No | H20: No | I20: 1 Major Surgery | J20: Yes | K20: =IF(J20="?","No",J20) -> Yes | N20: IF(H2="?","No",H2)
A21: Id20 | B21: 42.9 | C21: =IF(B21<18.5,"Under Weight",IF(B21<25,"Normal Weight",IF(B21<30,"Over Weight","Obesity"))) -> Obesity | D21: 11.41 | E21: =IF(D21<5.7,"Normal",IF(D21<6.4,"Prediabetes","Diabetes")) -> Diabetes | F21: No | G21: No | H21: No | I21: No Major Surgery | J21: Yes | K21: =IF(J21="?","No",J21) -> Yes
A22: Id21 | B22: 36.3 | C22: =IF(B22<18.5,"Under Weight",IF(B22<25,"Normal Weight",IF(B22<30,"Over Weight","Obesity"))) -> Obesity | D22: 11.5 | E22: =IF(D22<5.7,"Normal",IF(D22<6.4,"Prediabetes","Diabetes")) -> Diabetes | F22: Yes | G22: No | H22: No | I22: 2 Major Surgery | J22: Yes | K22: =IF(J22="?","No",J22) -> Yes
A23: Id22 | B23: 32.2 | C23: =IF(B23<18.5,"Under Weight",IF(B23<25,"Normal Weight",IF(B23<30,"Over Weight","Obesity"))) -> Obesity | D23: 6.22 | E23: =IF(D23<5.7,"Normal",IF(D23<6.4,"Prediabetes","Diabetes")) -> Prediabetes | F23: Yes | G23: No | H23: No | I23: 2 Major Surgery | J23: Yes | K23: =IF(J23="?","No",J23) -> Yes
A24: Id23 | B24: 31.3 | C24: =IF(B24<18.5,"Under Weight",IF(B24<25,"Normal Weight",IF(B24<30,"Over Weight","Obesity"))) -> Obesity | D24: 11.38 | E24: =IF(D24<5.7,"Normal",IF(D24<6.4,"Prediabetes","Diabetes")) -> Diabetes | F24: No | G24: No | H24: No | I24: 3 Major Surgery | J24: Yes | K24: =IF(J24="?","No",J24) -> Yes
A25: Id24 | B25: 41.8 | C25: =IF(B25<18.5,"Under Weight",IF(B25<25,"Normal Weight",IF(B25<30,"Over Weight","Obesity"))) -> Obesity | D25: 7.89 | E25: =IF(D25<5.7,"Normal",IF(D25<6.4,"Prediabetes","Diabetes")) -> Diabetes | F25: Yes | G25: No | H25: No | I25: 2 Major Surgery | J25: Yes | K25: =IF(J25="?","No",J25) -> Yes
A26: Id25 | B26: 35.09 | C26: =IF(B26<18.5,"Under Weight",IF(B26<25,"Normal Weight",IF(B26<30,"Over Weight","Obesity"))) -> Obesity | D26: 4.38 | E26: =IF(D26<5.7,"Normal",IF(D26<6.4,"Prediabetes","Diabetes")) -> Normal | F26: Yes | G26: No | H26: No | I26: 2 Major Surgery | J26: Yes | K26: =IF(J26="?","No",J26) -> Yes
A27: Id26 | B27: 33.88 | C27: =IF(B27<18.5,"Under Weight",IF(B27<25,"Normal Weight",IF(B27<30,"Over Weight","Obesity"))) -> Obesity | D27: 7.01 | E27: =IF(D27<5.7,"Normal",IF(D27<6.4,"Prediabetes","Diabetes")) -> Diabetes | F27: No | G27: No | H27: No | I27: 3 Major Surgery | J27: Yes | K27: =IF(J27="?","No",J27) -> Yes
A28: Id27 | B28: 30.875 | C28: =IF(B28<18.5,"Under Weight",IF(B28<25,"Normal Weight",IF(B28<30,"Over Weight","Obesity"))) -> Obesity | D28: 11.88 | E28: =IF(D28<5.7,"Normal",IF(D28<6.4,"Prediabetes","Diabetes")) -> Diabetes | F28: No | G28: No | H28: No | I28: No Major Surgery | J28: Yes | K28: =IF(J28="?","No",J28) -> Yes
A29: Id28 | B29: 36.86 | C29: =IF(B29<18.5,"Under Weight",IF(B29<25,"Normal Weight",IF(B29<30,"Over Weight","Obesity"))) -> Obesity | D29: 5.19 | E29: =IF(D29<5.7,"Normal",IF(D29<6.4,"Prediabetes","Diabetes")) -> Normal | F29: Yes | G29: No | H29: Yes | I29: 1 Major Surgery | J29: Yes | K29: =IF(J29="?","No",J29) -> Yes
A30: Id29 | B30: 35.86 | C30: =IF(B30<18.5,"Under Weight",IF(B30<25,"Normal Weight",IF(B30<30,"Over Weight","Obesity"))) -> Obesity | D30: 6.74 | E30: =IF(D30<5.7,"Normal",IF(D30<6.4,"Prediabetes","Diabetes")) -> Diabetes | F30: Yes | G30: No | H30: No | I30: 2 Major Surgery | J30: Yes | K30: =IF(J30="?","No",J30) -> Yes
A31: Id30 | B31: 37.05 | C31: =IF(B31<18.5,"Under Weight",IF(B31<25,"Normal Weight",IF(B31<30,"Over Weight","Obesity"))) -> Obesity | D31: 8.44 | E31: =IF(D31<5.7,"Normal",IF(D31<6.4,"Prediabetes","Diabetes")) -> Diabetes | F31: No | G31: No | H31: No | I31: No Major Surgery | J31: Yes | K31: =IF(J31="?","No",J31) -> Yes
A32: Id31 | B32: 43.89 | C32: =IF(B32<18.5,"Under Weight",IF(B32<25,"Normal Weight",IF(B32<30,"Over Weight","Obesity"))) -> Obesity | D32: 8.71 | E32: =IF(D32<5.7,"Normal",IF(D32<6.4,"Prediabetes","Diabetes")) -> Diabetes | F32: No | G32: No | H32: No | I32: No Major Surgery | J32: Yes | K32: =IF(J32="?","No",J32) -> Yes
... A2336: Id2335 | B2336: 17.58 | C2336: =IF(B2336<18.5,"Under Weight",IF(B2336<25,"Normal Weight",IF(B2336<30,"Over Weight","Obesity"))) -> Under Weight | D2336: 4.51 | E2336: =IF(D2336<5.7,"Normal",IF(D2336<6.4,"Prediabetes","Diabetes")) -> Normal | F2336: No | G2336: No | H2336: No | I2336: 1 Major Surgery | J2336: No | K2336: =IF(J2336="?","No",J2336) -> No

Sheet DataCleaning in Hospitalisation
A1: Customer ID | B1: Year | C1: Month | D1: Date | E1: Date of Birth | F1: Age | G1: Children | H1: Charges | I1: Hospital tier | J1: City tier | K1: State ID
A2: Id2335 | B2: 1992 | C2: Jul | D2: 9 | E2: =CONCATENATE(D2,"-",C2,"-",B2) -> 9-Jul-1992 | F2: =2023-B2 -> 31 | G2: 0 | H2: 563.84 | I2: tier - 2 | J2: tier - 3 | K2: R1013
A3: Id2334 | B3: 1992 | C3: Nov | D3: 30 | E3: =CONCATENATE(D3,"-",C3,"-",B3) -> 30-Nov-1992 | F3: =2023-B3 -> 31 | G3: 0 | H3: 570.62 | I3: tier - 2 | J3: tier - 1 | K3: R1013
A4: Id2333 | B4: 1993 | C4: Jun | D4: 30 | E4: =CONCATENATE(D4,"-",C4,"-",B4) -> 30-Jun-1993 | F4: =2023-B4 -> 30 | G4: 0 | H4: 600 | I4: tier - 2 | J4: tier - 1 | K4: R1013 | O4: Question No:1 | R4: Question No:2
A5: Id2332 | B5: 1992 | C5: Sep | D5: 13 | E5: =CONCATENATE(D5,"-",C5,"-",B5) -> 13-Sep-1992 | F5: =2023-B5 -> 31 | G5: 0 | H5: 604.54 | I5: tier - 3 | J5: tier - 3 | K5: R1013
A6: Id2331 | B6: 1998 | C6: Jul | D6: 27 | E6: =CONCATENATE(D6,"-",C6,"-",B6) -> 27-Jul-1998 | F6: =2023-B6 -> 25 | G6: 0 | H6: 637.26 | I6: tier - 3 | J6: tier - 3 | K6: R1013 | O6: DATA CLEANING | R6: DATA TRANSFORMATION
A7: Id2330 | B7: 2001 | C7: Nov | D7: 20 | E7: =CONCATENATE(D7,"-",C7,"-",B7) -> 20-Nov-2001 | F7: =2023-B7 -> 22 | G7: 0 | H7: 646.14 | I7: tier - 3 | J7: tier - 3 | K7: R1012
A8: Id2329 | B8: 1993 | C8: Jun | D8: 1 | E8: =CONCATENATE(D8,"-",C8,"-",B8) -> 1-Jun-1993 | F8: =2023-B8 -> 30 | G8: 0 | H8: 650 | I8: tier - 3 | J8: tier - 3 | K8: R1013 | O8: 1.Check the no of Missing Values in Hospitalisation Details | R8: 1.Convert the Numerical Data to Non Numerical Characters with Numerical Values
A9: Id2328 | B9: 1995 | C9: Jul | D9: 4 | E9: =CONCATENATE(D9,"-",C9,"-",B9) -> 4-Jul-1995 | F9: =2023-B9 -> 28 | G9: 0 | H9: 650 | I9: tier - 3 | J9: tier - 3 | K9: R1013
A10: Id2327 | B10: 2002 | C10: Nov | D10: 29 | E10: =CONCATENATE(D10,"-",C10,"-",B10) -> 29-Nov-2002 | F10: =2023-B10 -> 21 | G10: 0 | H10: 668 | I10: tier - 3 | J10: tier - 2 | K10: R1012 | O10: Using Countif Function | R10: Using Find and Replace function to replace the Numerical Data to Non Numerical Characters with Meaning Numerical values.
A11: Id2326 | B11: 1997 | C11: Nov | D11: 9 | E11: =CONCATENATE(D11,"-",C11,"-",B11) -> 9-Nov-1997 | F11: =2023-B11 -> 26 | G11: 0 | H11: 670 | I11: tier - 3 | J11: tier - 3 | K11: R1013 | O11: I find that Missing Values are there in six columns
A12: Id2325 | B12: 2001 | C12: Sep | D12: 12 | E12: =CONCATENATE(D12,"-",C12,"-",B12) -> 12-Sep-2001 | F12: =2023-B12 -> 22 | G12: 0 | H12: 687.54 | I12: tier - 3 | J12: tier - 2 | K12: R1013 | R12: 2.Check the inconsistent data in Heart Issue and Smoker Columns
A13: Id2324 | B13: 1999 | C13: Dec | D13: 26 | E13: =CONCATENATE(D13,"-",C13,"-",B13) -> 26-Dec-1999 | F13: =2023-B13 -> 24 | G13: 0 | H13: 700 | I13: tier - 2 | J13: tier - 3 | K13: R1013 | O13: Customer Id
A14: Id2323 | B14: 1999 | C14: Dec | D14: 14 | E14: =CONCATENATE(D14,"-",C14,"-",B14) -> 14-Dec-1999 | F14: =2023-B14 -> 24 | G14: 0 | H14: 722.99 | I14: tier - 3 | J14: tier - 1 | K14: R1013 | O14: COUNTIF(A1:A2338,"?") | R14: No Inconsistent Data in this columns
A15: Id2322 | B15: 2002 | C15: Sep | D15: 19 | E15: =CONCATENATE(D15,"-",C15,"-",B15) -> 19-Sep-2002 | F15: =2023-B15 -> 21 | G15: 0 | H15: 750 | I15: tier - 3 | J15: tier - 1 | K15: R1012 | O15: =COUNTIF(A2:A2339,"?") -> 0
A16: Id2321 | B16: 1993 | C16: Aug | D16: 9 | E16: =CONCATENATE(D16,"-",C16,"-",B16) -> 9-Aug-1993 | F16: =2023-B16 -> 30 | G16: 0 | H16: 760 | I16: tier - 3 | J16: tier - 1 | K16: R1013 | R16: 5.Merge the Date,Month and Year
A17: Id2320 | B17: 1996 | C17: Oct | D17: 22 | E17: =CONCATENATE(D17,"-",C17,"-",B17) -> 22-Oct-1996 | F17: =2023-B17 -> 27 | G17: 0 | H17: 760 | I17: tier - 3 | J17: tier - 3 | K17: R1013 | O17: Year
A18: Id2319 | B18: 1993 | C18: Jun | D18: 28 | E18: =CONCATENATE(D18,"-",C18,"-",B18) -> 28-Jun-1993 | F18: =2023-B18 -> 30 | G18: 0 | H18: 770 | I18: tier - 3 | J18: tier - 3 | K18: R1013 | O18: COUNTIF(B1:B2343,"?") | R18: Concatenate(D2,"-",C2,"-",B2)
A19: Id2318 | B19: 1996 | C19: Sep | D19: 18 | E19: =CONCATENATE(D19,"-",C19,"-",B19) -> 18-Sep-1996 | F19: =2023-B19 -> 27 | G19: 0 | H19: 770.38 | I19: tier - 3 | J19: tier - 2 | K19: R1012 | O19: =COUNTIF(B2:B2344,"?") -> 0
A20: Id2317 | B20: 1995 | C20: Dec | D20: 7 | E20: =CONCATENATE(D20,"-",C20,"-",B20) -> 7-Dec-1995 | F20: =2023-B20 -> 28 | G20: 0 | H20: 773.54 | I20: tier - 3 | J20: tier - 2 | K20: R1013
A21: Id2316 | B21: 2004 | C21: Oct | D21: 7 | E21: =CONCATENATE(D21,"-",C21,"-",B21) -> 7-Oct-2004 | F21: =2023-B21 -> 19 | G21: 0 | H21: 830.52 | I21: tier - 3 | J21: tier - 2 | K21: R1011
A22: Id2315 | B22: 2000 | C22: Nov | D22: 18 | E22: =CONCATENATE(D22,"-",C22,"-",B22) -> 18-Nov-2000 | F22: =2023-B22 -> 23 | G22: 0 | H22: 865.41 | I22: tier - 3 | J22: tier - 1 | K22: R1013 | O22: Month
A23: Id2314 | B23: 1993 | C23: Nov | D23: 27 | E23: =CONCATENATE(D23,"-",C23,"-",B23) -> 27-Nov-1993 | F23: =2023-B23 -> 30 | G23: 0 | H23: 896.21 | I23: tier - 3 | J23: tier - 1 | K23: R1013 | O23: COUNTIF(C1:C2343,"?")
A24: Id2313 | B24: 1994 | C24: Oct | D24: 30 | E24: =CONCATENATE(D24,"-",C24,"-",B24) -> 30-Oct-1994 | F24: =2023-B24 -> 29 | G24: 0 | H24: 915.07 | I24: tier - 3 | J24: tier - 1 | K24: R1013 | O24: =COUNTIF(C2:C2344,"?") -> 0
A25: Id2312 | B25: 1995 | C25: Oct | D25: 28 | E25: =CONCATENATE(D25,"-",C25,"-",B25) -> 28-Oct-1995 | F25: =2023-B25 -> 28 | G25: 0 | H25: 928.59 | I25: tier - 3 | J25: tier - 1 | K25: R1013
A26: Id2311 | B26: 2001 | C26: Aug | D26: 19 | E26: =CONCATENATE(D26,"-",C26,"-",B26) -> 19-Aug-2001 | F26: =2023-B26 -> 22 | G26: 0 | H26: 964.71 | I26: tier - 3 | J26: tier - 2 | K26: R1013 | O26: Date,Children and Charges columns are there is no missing values
A27: Id2310 | B27: 1994 | C27: Nov | D27: 22 | E27: =CONCATENATE(D27,"-",C27,"-",B27) -> 22-Nov-1994 | F27: =2023-B27 -> 29 | G27: 0 | H27: 1006.65 | I27: tier - 3 | J27: tier - 2 | K27: R1013
A28: Id2309 | B28: 2000 | C28: Oct | D28: 9 | E28: =CONCATENATE(D28,"-",C28,"-",B28) -> 9-Oct-2000 | F28: =2023-B28 -> 23 | G28: 0 | H28: 1012 | I28: tier - 3 | J28: tier - 2 | K28: R1013 | O28: Hospital tier
A29: Id2308 | B29: 1999 | C29: Aug | D29: 5 | E29: =CONCATENATE(D29,"-",C29,"-",B29) -> 5-Aug-1999 | F29: =2023-B29 -> 24 | G29: 0 | H29: 1019 | I29: tier - 3 | J29: tier - 2 | K29: R1013 | O29: COUNTIF(G1:G2343,"?")
A30: Id2307 | B30: 1995 | C30: Oct | D30: 5 | E30: =CONCATENATE(D30,"-",C30,"-",B30) -> 5-Oct-1995 | F30: =2023-B30 -> 28 | G30: 0 | H30: 1033.74 | I30: tier - 3 | J30: tier - 1 | K30: R1013 | O30: =COUNTIF(I2:I2344,"?") -> 0
A31: Id2306 | B31: 1994 | C31: Nov | D31: 17 | E31: =CONCATENATE(D31,"-",C31,"-",B31) -> 17-Nov-1994 | F31: =2023-B31 -> 29 | G31: 0 | H31: 1044 | I31: tier - 3 | J31: tier - 2 | K31: R1013
A32: Id2305 | B32: 2002 | C32: Jul | D32: 20 | E32: =CONCATENATE(D32,"-",C32,"-",B32) -> 20-Jul-2002 | F32: =2023-B32 -> 21 | G32: 0 | H32: 1047 | I32: tier - 3 | J32: tier - 1 | K32: R1013
A33: Id2304 | B33: 2002 | C33: Jul | D33: 1 | E33: =CONCATENATE(D33,"-",C33,"-",B33) -> 1-Jul-2002 | F33: =2023-B33 -> 21 | G33: 0 | H33: 1049 | I33: tier - 3 | J33: tier - 2 | K33: R1012 | O33: City tier
A34: Id2303 | B34: 1995 | C34: Jun | D34: 1 | E34: =CONCATENATE(D34,"-",C34,"-",B34) -> 1-Jun-1995 | F34: =2023-B34 -> 28 | G34: 0 | H34: 1056 | I34: tier - 3 | J34: tier - 2 | K34: R1013 | O34: COUNTIF(H1:H2343,"?")
A35: Id2302 | B35: 1993 | C35: Sep | D35: 28 | E35: =CONCATENATE(D35,"-",C35,"-",B35) -> 28-Sep-1993 | F35: =2023-B35 -> 30 | G35: 0 | H35: 1068 | I35: tier - 3 | J35: tier - 1 | K35: R1013 | O35: =COUNTIF(J2:J2344,"?") -> 0
A36: Id2301 | B36: 2004 | C36: Aug | D36: 24 | E36: =CONCATENATE(D36,"-",C36,"-",B36) -> 24-Aug-2004 | F36: =2023-B36 -> 19 | G36: 0 | H36: 1070 | I36: tier - 3 | J36: tier - 3 | K36: R1013
A37: Id2300 | B37: 1997 | C37: Aug | D37: 13 | E37: =CONCATENATE(D37,"-",C37,"-",B37) -> 13-Aug-1997 | F37: =2023-B37 -> 26 | G37: 0 | H37: 1071 | I37: tier - 3 | J37: tier - 3 | K37: R1013
A38: Id2299 | B38: 1998 | C38: Dec | D38: 26 | E38: =CONCATENATE(D38,"-",C38,"-",B38) -> 26-Dec-1998 | F38: =2023-B38 -> 25 | G38: 0 | H38: 1082 | I38: tier - 3 | J38: tier - 2 | K38: R1013 | O38: State ID
A39: Id2298 | B39: 2002 | C39: Aug | D39: 13 | E39: =CONCATENATE(D39,"-",C39,"-",B39) -> 13-Aug-2002 | F39: =2023-B39 -> 21 | G39: 0 | H39: 1086 | I39: tier - 3 | J39: tier - 3 | K39: R1013 | O39: COUNTIF(I1:I2343,"?")
A40: Id2297 | B40: 2004 | C40: Nov | D40: 12 | E40: =CONCATENATE(D40,"-",C40,"-",B40) -> 12-Nov-2004 | F40: =2023-B40 -> 19 | G40: 0 | H40: 1121.87 | I40: tier - 3 | J40: tier - 1 | K40: R1013 | O40: =COUNTIF(K2:K2344,"?") -> 0
...

Sheet Health Care
A1: Customer ID | B1: First Name | C1: BMI | D1: HBA1C | E1: Heart Issues | F1: Any Transplants | G1: Cancer History | H1: Number of Major Surgeries | I1: Smoker | J1: Weight Status | K1: Diabetes Status | L1: Date of Birth | M1: Charges | N1: Hospital Tier | O1: City Tier | P1: State ID | Q1: Age
A2: Id1 | B2: =_xlfn.XLOOKUP(A2,'Customer Names'!$A$2:$A$2336,'Customer Names'!$C$2:$C$2336) -> Ms.Kelly | C2: =_xlfn.XLOOKUP(A2,'Data Cleaning in Medical Examin'!$A$2:$A$2336,'Data Cleaning in Medical Examin'!$B$2:$B$2336) -> 47.41 | D2: =_xlfn.XLOOKUP(A2,'Data Cleaning in Medical Examin'!$A$2:$A$2336,'Data Cleaning in Medical Examin'!$D$2:$D$2336) -> 7.47 | E2: =_xlfn.XLOOKUP(A2,'Data Cleaning in Medical Examin'!$A$2:$A$2336,'Data Cleaning in Medical Examin'!$F$2:$F$2336) -> No | F2: =_xlfn.XLOOKUP(A2,'Data Cleaning in Medical Examin'!$A$2:$A$2336,'Data Cleaning in Medical Examin'!$G$2:$G$2336) -> No | G2: =_xlfn.XLOOKUP(A2,'Data Cleaning in Medical Examin'!$A$2:$A$2336,'Data Cleaning in Medical Examin'!$H$2:$H$2336) -> No | H2: =_xlfn.XLOOKUP(A2,'Data Cleaning in Medical Examin'!$A$2:$A$2336,'Data Cleaning in Medical Examin'!$I$2:$I$2336) -> No Major Surgery | I2: =_xlfn.XLOOKUP(A2,'Data Cleaning in Medical Examin'!$A$2:$A$2336,'Data Cleaning in Medical Examin'!$J$2:$J$2336) -> Yes | J2: =_xlfn.XLOOKUP(A2,'Data Cleaning in Medical Examin'!$A$2:$A$2336,'Data Cleaning in Medical Examin'!$C$2:$C$2336) -> Obesity | K2: =_xlfn.XLOOKUP(A2,'Data Cleaning in Medical Examin'!$A$2:$A$2336,'Data Cleaning in Medical Examin'!$E$2:$E$2336) -> Diabetes | L2: =_xlfn.XLOOKUP(A2,'DataCleaning in Hospitalisation'!$A$2:$A$2339,'DataCleaning in Hospitalisation'!$E$2:$E$2339) -> 4-Aug-1962 | M2: =_xlfn.XLOOKUP(A2,'DataCleaning in Hospitalisation'!$A$2:$A$2339,'DataCleaning in Hospitalisation'!$H$2:$H$2339) -> 52590.83 | N2: =_xlfn.XLOOKUP(A2,'DataCleaning in Hospitalisation'!$A$2:$A$2339,'DataCleaning in Hospitalisation'!$I$2:$I$2339) -> tier - 1 | O2: =_xlfn.XLOOKUP(A2,'DataCleaning in Hospitalisation'!$A$2:$A$2339,'DataCleaning in Hospitalisation'!$J$2:$J$2339) -> tier - 3 | P2: =_xlfn.XLOOKUP(A2,'DataCleaning in Hospitalisation'!$A$2:$A$2339,'DataCleaning in Hospitalisation'!$K$2:$K$2339) -> R1011 | Q2: =_xlfn.XLOOKUP(A2,'DataCleaning in Hospitalisation'!$A$2:$A$2339,'DataCleaning in Hospitalisation'!$F$2:$F$2339) -> 61 | U2: Row Labels | V2: Count of Charges | X2: Row Labels | Y2: Sum of Charges | AJ2: Row Labels | AK2: Average of Charges | AX2: Row Labels | AY2: Count of Charges
A3: Id2 | B3: =_xlfn.XLOOKUP(A3,'Customer Names'!$A$2:$A$2336,'Customer Names'!$C$2:$C$2336) -> Mr.Matthew | C3: =_xlfn.XLOOKUP(A3,'Data Cleaning in Medical Examin'!$A$2:$A$2336,'Data Cleaning in Medical Examin'!$B$2:$B$2336) -> 30.36 | D3: =_xlfn.XLOOKUP(A3,'Data Cleaning in Medical Examin'!$A$2:$A$2336,'Data Cleaning in Medical Examin'!$D$2:$D$2336) -> 5.77 | E3: =_xlfn.XLOOKUP(A3,'Data Cleaning in Medical Examin'!$A$2:$A$2336,'Data Cleaning in Medical Examin'!$F$2:$F$2336) -> No | F3: =_xlfn.XLOOKUP(A3,'Data Cleaning in Medical Examin'!$A$2:$A$2336,'Data Cleaning in Medical Examin'!$G$2:$G$2336) -> No | G3: =_xlfn.XLOOKUP(A3,'Data Cleaning in Medical Examin'!$A$2:$A$2336,'Data Cleaning in Medical Examin'!$H$2:$H$2336) -> No | H3: =_xlfn.XLOOKUP(A3,'Data Cleaning in Medical Examin'!$A$2:$A$2336,'Data Cleaning in Medical Examin'!$I$2:$I$2336) -> No Major Surgery | I3: =_xlfn.XLOOKUP(A3,'Data Cleaning in Medical Examin'!$A$2:$A$2336,'Data Cleaning in Medical Examin'!$J$2:$J$2336) -> Yes | J3: =_xlfn.XLOOKUP(A3,'Data Cleaning in Medical Examin'!$A$2:$A$2336,'Data Cleaning in Medical Examin'!$C$2:$C$2336) -> Obesity | K3: =_xlfn.XLOOKUP(A3,'Data Cleaning in Medical Examin'!$A$2:$A$2336,'Data Cleaning in Medical Examin'!$E$2:$E$2336) -> Prediabetes | L3: =_xlfn.XLOOKUP(A3,'DataCleaning in Hospitalisation'!$A$2:$A$2339,'DataCleaning in Hospitalisation'!$E$2:$E$2339) -> 27-Oct-1994 | M3: =_xlfn.XLOOKUP(A3,'DataCleaning in Hospitalisation'!$A$2:$A$2339,'DataCleaning in Hospitalisation'!$H$2:$H$2339) -> 51194.56 | N3: =_xlfn.XLOOKUP(A3,'DataCleaning in Hospitalisation'!$A$2:$A$2339,'DataCleaning in Hospitalisation'!$I$2:$I$2339) -> tier - 1 | O3: =_xlfn.XLOOKUP(A3,'DataCleaning in Hospitalisation'!$A$2:$A$2339,'DataCleaning in Hospitalisation'!$J$2:$J$2339) -> tier - 3 | P3: =_xlfn.XLOOKUP(A3,'DataCleaning in Hospitalisation'!$A$2:$A$2339,'DataCleaning in Hospitalisation'!$K$2:$K$2339) -> R1011 | Q3: =_xlfn.XLOOKUP(A3,'DataCleaning in Hospitalisation'!$A$2:$A$2339,'DataCleaning in Hospitalisation'!$F$2:$F$2339) -> 29 | U3: Id1 | V3: 1 | X3: Id1 | Y3: 52590.83 | AJ3: Id1 | AK3: 52590.83 | AX3: tier - 1 | AY3: 730
A4: Id3 | B4: =_xlfn.XLOOKUP(A4,'Customer Names'!$A$2:$A$2336,'Customer Names'!$C$2:$C$2336) -> Mr.Phil | C4: =_xlfn.XLOOKUP(A4,'Data Cleaning in Medical Examin'!$A$2:$A$2336,'Data Cleaning in Medical Examin'!$B$2:$B$2336) -> 34.485 | D4: =_xlfn.XLOOKUP(A4,'Data Cleaning in Medical Examin'!$A$2:$A$2336,'Data Cleaning in Medical Examin'!$D$2:$D$2336) -> 11.87 | E4: =_xlfn.XLOOKUP(A4,'Data Cleaning in Medical Examin'!$A$2:$A$2336,'Data Cleaning in Medical Examin'!$F$2:$F$2336) -> Yes | F4: =_xlfn.XLOOKUP(A4,'Data Cleaning in Medical Examin'!$A$2:$A$2336,'Data Cleaning in Medical Examin'!$G$2:$G$2336) -> No | G4: =_xlfn.XLOOKUP(A4,'Data Cleaning in Medical Examin'!$A$2:$A$2336,'Data Cleaning in Medical Examin'!$H$2:$H$2336) -> No | H4: =_xlfn.XLOOKUP(A4,'Data Cleaning in Medical Examin'!$A$2:$A$2336,'Data Cleaning in Medical Examin'!$I$2:$I$2336) -> 2 Major Surgery | I4: =_xlfn.XLOOKUP(A4,'Data Cleaning in Medical Examin'!$A$2:$A$2336,'Data Cleaning in Medical Examin'!$J$2:$J$2336) -> Yes | J4: =_xlfn.XLOOKUP(A4,'Data Cleaning in Medical Examin'!$A$2:$A$2336,'Data Cleaning in Medical Examin'!$C$2:$C$2336) -> Obesity | K4: =_xlfn.XLOOKUP(A4,'Data Cleaning in Medical Examin'!$A$2:$A$2336,'Data Cleaning in Medical Examin'!$E$2:$E$2336) -> Diabetes | L4: =_xlfn.XLOOKUP(A4,'DataCleaning in Hospitalisation'!$A$2:$A$2339,'DataCleaning in Hospitalisation'!$E$2:$E$2339) -> 27-Jun-1958 | M4: =_xlfn.XLOOKUP(A4,'DataCleaning in Hospitalisation'!$A$2:$A$2339,'DataCleaning in Hospitalisation'!$H$2:$H$2339) -> 49577.66 | N4: =_xlfn.XLOOKUP(A4,'DataCleaning in Hospitalisation'!$A$2:$A$2339,'DataCleaning in Hospitalisation'!$I$2:$I$2339) -> tier - 2 | O4: =_xlfn.XLOOKUP(A4,'DataCleaning in Hospitalisation'!$A$2:$A$2339,'DataCleaning in Hospitalisation'!$J$2:$J$2339) -> tier - 2 | P4: =_xlfn.XLOOKUP(A4,'DataCleaning in Hospitalisation'!$A$2:$A$2339,'DataCleaning in Hospitalisation'!$K$2:$K$2339) -> R1013 | Q4: =_xlfn.XLOOKUP(A4,'DataCleaning in Hospitalisation'!$A$2:$A$2339,'DataCleaning in Hospitalisation'!$F$2:$F$2339) -> 65 | U4: tier - 1 | V4: 1 | X4: Id10 | Y4: 48517.56 | AJ4: Id10 | AK4: 48517.56 | AX4: tier - 2 | AY4: 812
A5: Id4 | B5: =_xlfn.XLOOKUP(A5,'Customer Names'!$A$2:$A$2336,'Customer Names'!$C$2:$C$2336) -> Ms.Kelsey | C5: =_xlfn.XLOOKUP(A5,'Data Cleaning in Medical Examin'!$A$2:$A$2336,'Data Cleaning in Medical Examin'!$B$2:$B$2336) -> 38.095 | D5: =_xlfn.XLOOKUP(A5,'Data Cleaning in Medical Examin'!$A$2:$A$2336,'Data Cleaning in Medical Examin'!$D$2:$D$2336) -> 6.05 | E5: =_xlfn.XLOOKUP(A5,'Data Cleaning in Medical Examin'!$A$2:$A$2336,'Data Cleaning in Medical Examin'!$F$2:$F$2336) -> No | F5: =_xlfn.XLOOKUP(A5,'Data Cleaning in Medical Examin'!$A$2:$A$2336,'Data Cleaning in Medical Examin'!$G$2:$G$2336) -> No | G5: =_xlfn.XLOOKUP(A5,'Data Cleaning in Medical Examin'!$A$2:$A$2336,'Data Cleaning in Medical Examin'!$H$2:$H$2336) -> No | H5: =_xlfn.XLOOKUP(A5,'Data Cleaning in Medical Examin'!$A$2:$A$2336,'Data Cleaning in Medical Examin'!$I$2:$I$2336) -> No Major Surgery | I5: =_xlfn.XLOOKUP(A5,'Data Cleaning in Medical Examin'!$A$2:$A$2336,'Data Cleaning in Medical Examin'!$J$2:$J$2336) -> Yes | J5: =_xlfn.XLOOKUP(A5,'Data Cleaning in Medical Examin'!$A$2:$A$2336,'Data Cleaning in Medical Examin'!$C$2:$C$2336) -> Obesity | K5: =_xlfn.XLOOKUP(A5,'Data Cleaning in Medical Examin'!$A$2:$A$2336,'Data Cleaning in Medical Examin'!$E$2:$E$2336) -> Prediabetes | L5: =_xlfn.XLOOKUP(A5,'DataCleaning in Hospitalisation'!$A$2:$A$2339,'DataCleaning in Hospitalisation'!$E$2:$E$2339) -> 4-Sep-1963 | M5: =_xlfn.XLOOKUP(A5,'DataCleaning in Hospitalisation'!$A$2:$A$2339,'DataCleaning in Hospitalisation'!$H$2:$H$2339) -> 48970.25 | N5: =_xlfn.XLOOKUP(A5,'DataCleaning in Hospitalisation'!$A$2:$A$2339,'DataCleaning in Hospitalisation'!$I$2:$I$2339) -> tier - 1 | O5: =_xlfn.XLOOKUP(A5,'DataCleaning in Hospitalisation'!$A$2:$A$2339,'DataCleaning in Hospitalisation'!$J$2:$J$2339) -> tier - 2 | P5: =_xlfn.XLOOKUP(A5,'DataCleaning in Hospitalisation'!$A$2:$A$2339,'DataCleaning in Hospitalisation'!$K$2:$K$2339) -> R1013 | Q5: =_xlfn.XLOOKUP(A5,'DataCleaning in Hospitalisation'!$A$2:$A$2339,'DataCleaning in Hospitalisation'!$F$2:$F$2339) -> 60 | U5: No Major Surgery | V5: 1 | X5: Id100 | Y5: 40103.89 | AJ5: Id100 | AK5: 40103.89 | AX5: tier - 3 | AY5: 793
A6: Id5 | B6: =_xlfn.XLOOKUP(A6,'Customer Names'!$A$2:$A$2336,'Customer Names'!$C$2:$C$2336) -> Ms.Kristyn | C6: =_xlfn.XLOOKUP(A6,'Data Cleaning in Medical Examin'!$A$2:$A$2336,'Data Cleaning in Medical Examin'!$B$2:$B$2336) -> 35.53 | D6: =_xlfn.XLOOKUP(A6,'Data Cleaning in Medical Examin'!$A$2:$A$2336,'Data Cleaning in Medical Examin'!$D$2:$D$2336) -> 5.45 | E6: =_xlfn.XLOOKUP(A6,'Data Cleaning in Medical Examin'!$A$2:$A$2336,'Data Cleaning in Medical Examin'!$F$2:$F$2336) -> No | F6: =_xlfn.XLOOKUP(A6,'Data Cleaning in Medical Examin'!$A$2:$A$2336,'Data Cleaning in Medical Examin'!$G$2:$G$2336) -> No | G6: =_xlfn.XLOOKUP(A6,'Data Cleaning in Medical Examin'!$A$2:$A$2336,'Data Cleaning in Medical Examin'!$H$2:$H$2336) -> No | H6: =_xlfn.XLOOKUP(A6,'Data Cleaning in Medical Examin'!$A$2:$A$2336,'Data Cleaning in Medical Examin'!$I$2:$I$2336) -> No Major Surgery | I6: =_xlfn.XLOOKUP(A6,'Data Cleaning in Medical Examin'!$A$2:$A$2336,'Data Cleaning in Medical Examin'!$J$2:$J$2336) -> Yes | J6: =_xlfn.XLOOKUP(A6,'Data Cleaning in Medical Examin'!$A$2:$A$2336,'Data Cleaning in Medical Examin'!$C$2:$C$2336) -> Obesity | K6: =_xlfn.XLOOKUP(A6,'Data Cleaning in Medical Examin'!$A$2:$A$2336,'Data Cleaning in Medical Examin'!$E$2:$E$2336) -> Normal | L6: =_xlfn.XLOOKUP(A6,'DataCleaning in Hospitalisation'!$A$2:$A$2339,'DataCleaning in Hospitalisation'!$E$2:$E$2339) -> 29-Dec-1978 | M6: =_xlfn.XLOOKUP(A6,'DataCleaning in Hospitalisation'!$A$2:$A$2339,'DataCleaning in Hospitalisation'!$H$2:$H$2339) -> 48885.14 | N6: =_xlfn.XLOOKUP(A6,'DataCleaning in Hospitalisation'!$A$2:$A$2339,'DataCleaning in Hospitalisation'!$I$2:$I$2339) -> tier - 1 | O6: =_xlfn.XLOOKUP(A6,'DataCleaning in Hospitalisation'!$A$2:$A$2339,'DataCleaning in Hospitalisation'!$J$2:$J$2339) -> tier - 2 | P6: =_xlfn.XLOOKUP(A6,'DataCleaning in Hospitalisation'!$A$2:$A$2339,'DataCleaning in Hospitalisation'!$K$2:$K$2339) -> R1013 | Q6: =_xlfn.XLOOKUP(A6,'DataCleaning in Hospitalisation'!$A$2:$A$2339,'DataCleaning in Hospitalisation'!$F$2:$F$2339) -> 45 | U6: tier - 3 | V6: 1 | X6: Id1000 | Y6: 11217.35 | AJ6: Id1000 | AK6: 11217.35 | AX6: Grand Total | AY6: 2335
A7: Id6 | B7: =_xlfn.XLOOKUP(A7,'Customer Names'!$A$2:$A$2336,'Customer Names'!$C$2:$C$2336) -> Mr.Russell | C7: =_xlfn.XLOOKUP(A7,'Data Cleaning in Medical Examin'!$A$2:$A$2336,'Data Cleaning in Medical Examin'!$B$2:$B$2336) -> 32.8 | D7: =_xlfn.XLOOKUP(A7,'Data Cleaning in Medical Examin'!$A$2:$A$2336,'Data Cleaning in Medical Examin'!$D$2:$D$2336) -> 6.59 | E7: =_xlfn.XLOOKUP(A7,'Data Cleaning in Medical Examin'!$A$2:$A$2336,'Data Cleaning in Medical Examin'!$F$2:$F$2336) -> No | F7: =_xlfn.XLOOKUP(A7,'Data Cleaning in Medical Examin'!$A$2:$A$2336,'Data Cleaning in Medical Examin'!$G$2:$G$2336) -> No | G7: =_xlfn.XLOOKUP(A7,'Data Cleaning in Medical Examin'!$A$2:$A$2336,'Data Cleaning in Medical Examin'!$H$2:$H$2336) -> No | H7: =_xlfn.XLOOKUP(A7,'Data Cleaning in Medical Examin'!$A$2:$A$2336,'Data Cleaning in Medical Examin'!$I$2:$I$2336) -> No Major Surgery | I7: =_xlfn.XLOOKUP(A7,'Data Cleaning in Medical Examin'!$A$2:$A$2336,'Data Cleaning in Medical Examin'!$J$2:$J$2336) -> Yes | J7: =_xlfn.XLOOKUP(A7,'Data Cleaning in Medical Examin'!$A$2:$A$2336,'Data Cleaning in Medical Examin'!$C$2:$C$2336) -> Obesity | K7: =_xlfn.XLOOKUP(A7,'Data Cleaning in Medical Examin'!$A$2:$A$2336,'Data Cleaning in Medical Examin'!$E$2:$E$2336) -> Diabetes | L7: =_xlfn.XLOOKUP(A7,'DataCleaning in Hospitalisation'!$A$2:$A$2339,'DataCleaning in Hospitalisation'!$E$2:$E$2339) -> 22-Jul-1959 | M7: =_xlfn.XLOOKUP(A7,'DataCleaning in Hospitalisation'!$A$2:$A$2339,'DataCleaning in Hospitalisation'!$H$2:$H$2339) -> 48824.45 | N7: =_xlfn.XLOOKUP(A7,'DataCleaning in Hospitalisation'!$A$2:$A$2339,'DataCleaning in Hospitalisation'!$I$2:$I$2339) -> tier - 2 | O7: =_xlfn.XLOOKUP(A7,'DataCleaning in Hospitalisation'!$A$2:$A$2339,'DataCleaning in Hospitalisation'!$J$2:$J$2339) -> tier - 1 | P7: =_xlfn.XLOOKUP(A7,'DataCleaning in Hospitalisation'!$A$2:$A$2339,'DataCleaning in Hospitalisation'!$K$2:$K$2339) -> R1011 | Q7: =_xlfn.XLOOKUP(A7,'DataCleaning in Hospitalisation'!$A$2:$A$2339,'DataCleaning in Hospitalisation'!$F$2:$F$2339) -> 64 | U7: No | V7: 1 | X7: Id1001 | Y7: 11187.66 | AJ7: Id1001 | AK7: 11187.66
A8: Id7 | B8: =_xlfn.XLOOKUP(A8,'Customer Names'!$A$2:$A$2336,'Customer Names'!$C$2:$C$2336) -> Mr.Scott | C8: =_xlfn.XLOOKUP(A8,'Data Cleaning in Medical Examin'!$A$2:$A$2336,'Data Cleaning in Medical Examin'!$B$2:$B$2336) -> 36.4 | D8: =_xlfn.XLOOKUP(A8,'Data Cleaning in Medical Examin'!$A$2:$A$2336,'Data Cleaning in Medical Examin'!$D$2:$D$2336) -> 6.07 | E8: =_xlfn.XLOOKUP(A8,'Data Cleaning in Medical Examin'!$A$2:$A$2336,'Data Cleaning in Medical Examin'!$F$2:$F$2336) -> No | F8: =_xlfn.XLOOKUP(A8,'Data Cleaning in Medical Examin'!$A$2:$A$2336,'Data Cleaning in Medical Examin'!$G$2:$G$2336) -> No | G8: =_xlfn.XLOOKUP(A8,'Data Cleaning in Medical Examin'!$A$2:$A$2336,'Data Cleaning in Medical Examin'!$H$2:$H$2336) -> No | H8: =_xlfn.XLOOKUP(A8,'Data Cleaning in Medical Examin'!$A$2:$A$2336,'Data Cleaning in Medical Examin'!$I$2:$I$2336) -> No Major Surgery | I8: =_xlfn.XLOOKUP(A8,'Data Cleaning in Medical Examin'!$A$2:$A$2336,'Data Cleaning in Medical Examin'!$J$2:$J$2336) -> Yes | J8: =_xlfn.XLOOKUP(A8,'Data Cleaning in Medical Examin'!$A$2:$A$2336,'Data Cleaning in Medical Examin'!$C$2:$C$2336) -> Obesity | K8: =_xlfn.XLOOKUP(A8,'Data Cleaning in Medical Examin'!$A$2:$A$2336,'Data Cleaning in Medical Examin'!$E$2:$E$2336) -> Prediabetes | L8: =_xlfn.XLOOKUP(A8,'DataCleaning in Hospitalisation'!$A$2:$A$2339,'DataCleaning in Hospitalisation'!$E$2:$E$2339) -> 27-Oct-1965 | M8: =_xlfn.XLOOKUP(A8,'DataCleaning in Hospitalisation'!$A$2:$A$2339,'DataCleaning in Hospitalisation'!$H$2:$H$2339) -> 48675.52 | N8: =_xlfn.XLOOKUP(A8,'DataCleaning in Hospitalisation'!$A$2:$A$2339,'DataCleaning in Hospitalisation'!$I$2:$I$2339) -> tier - 1 | O8: =_xlfn.XLOOKUP(A8,'DataCleaning in Hospitalisation'!$A$2:$A$2339,'DataCleaning in Hospitalisation'!$J$2:$J$2339) -> tier - 2 | P8: =_xlfn.XLOOKUP(A8,'DataCleaning in Hospitalisation'!$A$2:$A$2339,'DataCleaning in Hospitalisation'!$K$2:$K$2339) -> R1013 | Q8: =_xlfn.XLOOKUP(A8,'DataCleaning in Hospitalisation'!$A$2:$A$2339,'DataCleaning in Hospitalisation'!$F$2:$F$2339) -> 58 | U8: No | V8: 1 | X8: Id1002 | Y8: 11186.2 | AJ8: Id1002 | AK8: 11186.2
A9: Id8 | B9: =_xlfn.XLOOKUP(A9,'Customer Names'!$A$2:$A$2336,'Customer Names'!$C$2:$C$2336) -> Mr.Stephen | C9: =_xlfn.XLOOKUP(A9,'Data Cleaning in Medical Examin'!$A$2:$A$2336,'Data Cleaning in Medical Examin'!$B$2:$B$2336) -> 36.96 | D9: =_xlfn.XLOOKUP(A9,'Data Cleaning in Medical Examin'!$A$2:$A$2336,'Data Cleaning in Medical Examin'!$D$2:$D$2336) -> 7.93 | E9: =_xlfn.XLOOKUP(A9,'Data Cleaning in Medical Examin'!$A$2:$A$2336,'Data Cleaning in Medical Examin'!$F$2:$F$2336) -> No | F9: =_xlfn.XLOOKUP(A9,'Data Cleaning in Medical Examin'!$A$2:$A$2336,'Data Cleaning in Medical Examin'!$G$2:$G$2336) -> No | G9: =_xlfn.XLOOKUP(A9,'Data Cleaning in Medical Examin'!$A$2:$A$2336,'Data Cleaning in Medical Examin'!$H$2:$H$2336) -> No | H9: =_xlfn.XLOOKUP(A9,'Data Cleaning in Medical Examin'!$A$2:$A$2336,'Data Cleaning in Medical Examin'!$I$2:$I$2336) -> 3 Major Surgery | I9: =_xlfn.XLOOKUP(A9,'Data Cleaning in Medical Examin'!$A$2:$A$2336,'Data Cleaning in Medical Examin'!$J$2:$J$2336) -> Yes | J9: =_xlfn.XLOOKUP(A9,'Data Cleaning in Medical Examin'!$A$2:$A$2336,'Data Cleaning in Medical Examin'!$C$2:$C$2336) -> Obesity | K9: =_xlfn.XLOOKUP(A9,'Data Cleaning in Medical Examin'!$A$2:$A$2336,'Data Cleaning in Medical Examin'!$E$2:$E$2336) -> Diabetes | L9: =_xlfn.XLOOKUP(A9,'DataCleaning in Hospitalisation'!$A$2:$A$2339,'DataCleaning in Hospitalisation'!$E$2:$E$2339) -> 11-Oct-1962 | M9: =_xlfn.XLOOKUP(A9,'DataCleaning in Hospitalisation'!$A$2:$A$2339,'DataCleaning in Hospitalisation'!$H$2:$H$2339) -> 48673.56 | N9: =_xlfn.XLOOKUP(A9,'DataCleaning in Hospitalisation'!$A$2:$A$2339,'DataCleaning in Hospitalisation'!$I$2:$I$2339) -> tier - 1 | O9: =_xlfn.XLOOKUP(A9,'DataCleaning in Hospitalisation'!$A$2:$A$2339,'DataCleaning in Hospitalisation'!$J$2:$J$2339) -> tier - 2 | P9: =_xlfn.XLOOKUP(A9,'DataCleaning in Hospitalisation'!$A$2:$A$2339,'DataCleaning in Hospitalisation'!$K$2:$K$2339) -> R1013 | Q9: =_xlfn.XLOOKUP(A9,'DataCleaning in Hospitalisation'!$A$2:$A$2339,'DataCleaning in Hospitalisation'!$F$2:$F$2339) -> 61 | U9: Id10 | V9: 1 | X9: Id1003 | Y9: 11165.42 | AJ9: Id1003 | AK9: 11165.42
A10: Id9 | B10: =_xlfn.XLOOKUP(A10,'Customer Names'!$A$2:$A$2336,'Customer Names'!$C$2:$C$2336) -> Mr.Patrick | C10: =_xlfn.XLOOKUP(A10,'Data Cleaning in Medical Examin'!$A$2:$A$2336,'Data Cleaning in Medical Examin'!$B$2:$B$2336) -> 41.14 | D10: =_xlfn.XLOOKUP(A10,'Data Cleaning in Medical Examin'!$A$2:$A$2336,'Data Cleaning in Medical Examin'!$D$2:$D$2336) -> 9.58 | E10: =_xlfn.XLOOKUP(A10,'Data Cleaning in Medical Examin'!$A$2:$A$2336,'Data Cleaning in Medical Examin'!$F$2:$F$2336) -> Yes | F10: =_xlfn.XLOOKUP(A10,'Data Cleaning in Medical Examin'!$A$2:$A$2336,'Data Cleaning in Medical Examin'!$G$2:$G$2336) -> No | G10: =_xlfn.XLOOKUP(A10,'Data Cleaning in Medical Examin'!$A$2:$A$2336,'Data Cleaning in Medical Examin'!$H$2:$H$2336) -> Yes | H10: =_xlfn.XLOOKUP(A10,'Data Cleaning in Medical Examin'!$A$2:$A$2336,'Data Cleaning in Medical Examin'!$I$2:$I$2336) -> 1 Major Surgery | I10: =_xlfn.XLOOKUP(A10,'Data Cleaning in Medical Examin'!$A$2:$A$2336,'Data Cleaning in Medical Examin'!$J$2:$J$2336) -> Yes | J10: =_xlfn.XLOOKUP(A10,'Data Cleaning in Medical Examin'!$A$2:$A$2336,'Data Cleaning in Medical Examin'!$C$2:$C$2336) -> Obesity | K10: =_xlfn.XLOOKUP(A10,'Data Cleaning in Medical Examin'!$A$2:$A$2336,'Data Cleaning in Medical Examin'!$E$2:$E$2336) -> Diabetes | L10: =_xlfn.XLOOKUP(A10,'DataCleaning in Hospitalisation'!$A$2:$A$2339,'DataCleaning in Hospitalisation'!$E$2:$E$2339) -> 1-Dec-1968 | M10: =_xlfn.XLOOKUP(A10,'DataCleaning in Hospitalisation'!$A$2:$A$2339,'DataCleaning in Hospitalisation'!$H$2:$H$2339) -> 48549.18 | N10: =_xlfn.XLOOKUP(A10,'DataCleaning in Hospitalisation'!$A$2:$A$2339,'DataCleaning in Hospitalisation'!$I$2:$I$2339) -> tier - 1 | O10: =_xlfn.XLOOKUP(A10,'DataCleaning in Hospitalisation'!$A$2:$A$2339,'DataCleaning in Hospitalisation'!$J$2:$J$2339) -> tier - 3 | P10: =_xlfn.XLOOKUP(A10,'DataCleaning in Hospitalisation'!$A$2:$A$2339,'DataCleaning in Hospitalisation'!$K$2:$K$2339) -> R1016 | Q10: =_xlfn.XLOOKUP(A10,'DataCleaning in Hospitalisation'!$A$2:$A$2339,'DataCleaning in Hospitalisation'!$F$2:$F$2339) -> 55 | U10: tier - 1 | V10: 1 | X10: Id1004 | Y10: 11163.57 | AJ10: Id1004 | AK10: 11163.57
A11: Id10 | B11: =_xlfn.XLOOKUP(A11,'Customer Names'!$A$2:$A$2336,'Customer Names'!$C$2:$C$2336) -> Ms.Brooke | C11: =_xlfn.XLOOKUP(A11,'Data Cleaning in Medical Examin'!$A$2:$A$2336,'Data Cleaning in Medical Examin'!$B$2:$B$2336) -> 38.06 | D11: =_xlfn.XLOOKUP(A11,'Data Cleaning in Medical Examin'!$A$2:$A$2336,'Data Cleaning in Medical Examin'!$D$2:$D$2336) -> 10.79 | E11: =_xlfn.XLOOKUP(A11,'Data Cleaning in Medical Examin'!$A$2:$A$2336,'Data Cleaning in Medical Examin'!$F$2:$F$2336) -> No | F11: =_xlfn.XLOOKUP(A11,'Data Cleaning in Medical Examin'!$A$2:$A$2336,'Data Cleaning in Medical Examin'!$G$2:$G$2336) -> No | G11: =_xlfn.XLOOKUP(A11,'Data Cleaning in Medical Examin'!$A$2:$A$2336,'Data Cleaning in Medical Examin'!$H$2:$H$2336) -> No | H11: =_xlfn.XLOOKUP(A11,'Data Cleaning in Medical Examin'!$A$2:$A$2336,'Data Cleaning in Medical Examin'!$I$2:$I$2336) -> No Major Surgery | I11: =_xlfn.XLOOKUP(A11,'Data Cleaning in Medical Examin'!$A$2:$A$2336,'Data Cleaning in Medical Examin'!$J$2:$J$2336) -> Yes | J11: =_xlfn.XLOOKUP(A11,'Data Cleaning in Medical Examin'!$A$2:$A$2336,'Data Cleaning in Medical Examin'!$C$2:$C$2336) -> Obesity | K11: =_xlfn.XLOOKUP(A11,'Data Cleaning in Medical Examin'!$A$2:$A$2336,'Data Cleaning in Medical Examin'!$E$2:$E$2336) -> Diabetes | L11: =_xlfn.XLOOKUP(A11,'DataCleaning in Hospitalisation'!$A$2:$A$2339,'DataCleaning in Hospitalisation'!$E$2:$E$2339) -> 21-Dec-1961 | M11: =_xlfn.XLOOKUP(A11,'DataCleaning in Hospitalisation'!$A$2:$A$2339,'DataCleaning in Hospitalisation'!$H$2:$H$2339) -> 48517.56 | N11: =_xlfn.XLOOKUP(A11,'DataCleaning in Hospitalisation'!$A$2:$A$2339,'DataCleaning in Hospitalisation'!$I$2:$I$2339) -> tier - 1 | O11: =_xlfn.XLOOKUP(A11,'DataCleaning in Hospitalisation'!$A$2:$A$2339,'DataCleaning in Hospitalisation'!$J$2:$J$2339) -> tier - 3 | P11: =_xlfn.XLOOKUP(A11,'DataCleaning in Hospitalisation'!$A$2:$A$2339,'DataCleaning in Hospitalisation'!$K$2:$K$2339) -> R1024 | Q11: =_xlfn.XLOOKUP(A11,'DataCleaning in Hospitalisation'!$A$2:$A$2339,'DataCleaning in Hospitalisation'!$F$2:$F$2339) -> 62 | U11: No Major Surgery | V11: 1 | X11: Id1005 | Y11: 11150.78 | AJ11: Id1005 | AK11: 11150.78
A12: Id11 | B12: =_xlfn.XLOOKUP(A12,'Customer Names'!$A$2:$A$2336,'Customer Names'!$C$2:$C$2336) -> Ms.Paola | C12: =_xlfn.XLOOKUP(A12,'Data Cleaning in Medical Examin'!$A$2:$A$2336,'Data Cleaning in Medical Examin'!$B$2:$B$2336) -> 37.7 | D12: =_xlfn.XLOOKUP(A12,'Data Cleaning in Medical Examin'!$A$2:$A$2336,'Data Cleaning in Medical Examin'!$D$2:$D$2336) -> 5.96 | E12: =_xlfn.XLOOKUP(A12,'Data Cleaning in Medical Examin'!$A$2:$A$2336,'Data Cleaning in Medical Examin'!$F$2:$F$2336) -> Yes | F12: =_xlfn.XLOOKUP(A12,'Data Cleaning in Medical Examin'!$A$2:$A$2336,'Data Cleaning in Medical Examin'!$G$2:$G$2336) -> No | G12: =_xlfn.XLOOKUP(A12,'Data Cleaning in Medical Examin'!$A$2:$A$2336,'Data Cleaning in Medical Examin'!$H$2:$H$2336) -> No | H12: =_xlfn.XLOOKUP(A12,'Data Cleaning in Medical Examin'!$A$2:$A$2336,'Data Cleaning in Medical Examin'!$I$2:$I$2336) -> 2 Major Surgery | I12: =_xlfn.XLOOKUP(A12,'Data Cleaning in Medical Examin'!$A$2:$A$2336,'Data Cleaning in Medical Examin'!$J$2:$J$2336) -> Yes | J12: =_xlfn.XLOOKUP(A12,'Data Cleaning in Medical Examin'!$A$2:$A$2336,'Data Cleaning in Medical Examin'!$C$2:$C$2336) -> Obesity | K12: =_xlfn.XLOOKUP(A12,'Data Cleaning in Medical Examin'!$A$2:$A$2336,'Data Cleaning in Medical Examin'!$E$2:$E$2336) -> Prediabetes | L12: =_xlfn.XLOOKUP(A12,'DataCleaning in Hospitalisation'!$A$2:$A$2339,'DataCleaning in Hospitalisation'!$E$2:$E$2339) -> 27-Aug-1962 | M12: =_xlfn.XLOOKUP(A12,'DataCleaning in Hospitalisation'!$A$2:$A$2339,'DataCleaning in Hospitalisation'!$H$2:$H$2339) -> 48173.36 | N12: =_xlfn.XLOOKUP(A12,'DataCleaning in Hospitalisation'!$A$2:$A$2339,'DataCleaning in Hospitalisation'!$I$2:$I$2339) -> tier - 1 | O12: =_xlfn.XLOOKUP(A12,'DataCleaning in Hospitalisation'!$A$2:$A$2339,'DataCleaning in Hospitalisation'!$J$2:$J$2339) -> tier - 3 | P12: =_xlfn.XLOOKUP(A12,'DataCleaning in Hospitalisation'!$A$2:$A$2339,'DataCleaning in Hospitalisation'!$K$2:$K$2339) -> R1011 | Q12: =_xlfn.XLOOKUP(A12,'DataCleaning in Hospitalisation'!$A$2:$A$2339,'DataCleaning in Hospitalisation'!$F$2:$F$2339) -> 61 | U12: tier - 3 | V12: 1 | X12: Id1006 | Y12: 11103.33 | AJ12: Id1006 | AK12: 11103.33
A13: Id12 | B13: =_xlfn.XLOOKUP(A13,'Customer Names'!$A$2:$A$2336,'Customer Names'!$C$2:$C$2336) -> Mr.David | C13: =_xlfn.XLOOKUP(A13,'Data Cleaning in Medical Examin'!$A$2:$A$2336,'Data Cleaning in Medical Examin'!$B$2:$B$2336) -> 42.13 | D13: =_xlfn.XLOOKUP(A13,'Data Cleaning in Medical Examin'!$A$2:$A$2336,'Data Cleaning in Medical Examin'!$D$2:$D$2336) -> 11.9 | E13: =_xlfn.XLOOKUP(A13,'Data Cleaning in Medical Examin'!$A$2:$A$2336,'Data Cleaning in Medical Examin'!$F$2:$F$2336) -> No | F13: =_xlfn.XLOOKUP(A13,'Data Cleaning in Medical Examin'!$A$2:$A$2336,'Data Cleaning in Medical Examin'!$G$2:$G$2336) -> No | G13: =_xlfn.XLOOKUP(A13,'Data Cleaning in Medical Examin'!$A$2:$A$2336,'Data Cleaning in Medical Examin'!$H$2:$H$2336) -> No | H13: =_xlfn.XLOOKUP(A13,'Data Cleaning in Medical Examin'!$A$2:$A$2336,'Data Cleaning in Medical Examin'!$I$2:$I$2336) -> No Major Surgery | I13: =_xlfn.XLOOKUP(A13,'Data Cleaning in Medical Examin'!$A$2:$A$2336,'Data Cleaning in Medical Examin'!$J$2:$J$2336) -> Yes | J13: =_xlfn.XLOOKUP(A13,'Data Cleaning in Medical Examin'!$A$2:$A$2336,'Data Cleaning in Medical Examin'!$C$2:$C$2336) -> Obesity | K13: =_xlfn.XLOOKUP(A13,'Data Cleaning in Medical Examin'!$A$2:$A$2336,'Data Cleaning in Medical Examin'!$E$2:$E$2336) -> Diabetes | L13: =_xlfn.XLOOKUP(A13,'DataCleaning in Hospitalisation'!$A$2:$A$2339,'DataCleaning in Hospitalisation'!$E$2:$E$2339) -> 16-Nov-1958 | M13: =_xlfn.XLOOKUP(A13,'DataCleaning in Hospitalisation'!$A$2:$A$2339,'DataCleaning in Hospitalisation'!$H$2:$H$2339) -> 47928.03 | N13: =_xlfn.XLOOKUP(A13,'DataCleaning in Hospitalisation'!$A$2:$A$2339,'DataCleaning in Hospitalisation'!$I$2:$I$2339) -> tier - 2 | O13: =_xlfn.XLOOKUP(A13,'DataCleaning in Hospitalisation'!$A$2:$A$2339,'DataCleaning in Hospitalisation'!$J$2:$J$2339) -> tier - 3 | P13: =_xlfn.XLOOKUP(A13,'DataCleaning in Hospitalisation'!$A$2:$A$2339,'DataCleaning in Hospitalisation'!$K$2:$K$2339) -> R1011 | Q13: =_xlfn.XLOOKUP(A13,'DataCleaning in Hospitalisation'!$A$2:$A$2339,'DataCleaning in Hospitalisation'!$F$2:$F$2339) -> 65 | U13: No | V13: 1 | X13: Id1007 | Y13: 11093.62 | AJ13: Id1007 | AK13: 11093.62
A14: Id13 | B14: =_xlfn.XLOOKUP(A14,'Customer Names'!$A$2:$A$2336,'Customer Names'!$C$2:$C$2336) -> Mr.Wade | C14: =_xlfn.XLOOKUP(A14,'Data Cleaning in Medical Examin'!$A$2:$A$2336,'Data Cleaning in Medical Examin'!$B$2:$B$2336) -> 40.92 | D14: =_xlfn.XLOOKUP(A14,'Data Cleaning in Medical Examin'!$A$2:$A$2336,'Data Cleaning in Medical Examin'!$D$2:$D$2336) -> 8.41 | E14: =_xlfn.XLOOKUP(A14,'Data Cleaning in Medical Examin'!$A$2:$A$2336,'Data Cleaning in Medical Examin'!$F$2:$F$2336) -> No | F14: =_xlfn.XLOOKUP(A14,'Data Cleaning in Medical Examin'!$A$2:$A$2336,'Data Cleaning in Medical Examin'!$G$2:$G$2336) -> No | G14: =_xlfn.XLOOKUP(A14,'Data Cleaning in Medical Examin'!$A$2:$A$2336,'Data Cleaning in Medical Examin'!$H$2:$H$2336) -> No | H14: =_xlfn.XLOOKUP(A14,'Data Cleaning in Medical Examin'!$A$2:$A$2336,'Data Cleaning in Medical Examin'!$I$2:$I$2336) -> No Major Surgery | I14: =_xlfn.XLOOKUP(A14,'Data Cleaning in Medical Examin'!$A$2:$A$2336,'Data Cleaning in Medical Examin'!$J$2:$J$2336) -> Yes | J14: =_xlfn.XLOOKUP(A14,'Data Cleaning in Medical Examin'!$A$2:$A$2336,'Data Cleaning in Medical Examin'!$C$2:$C$2336) -> Obesity | K14: =_xlfn.XLOOKUP(A14,'Data Cleaning in Medical Examin'!$A$2:$A$2336,'Data Cleaning in Medical Examin'!$E$2:$E$2336) -> Diabetes | L14: =_xlfn.XLOOKUP(A14,'DataCleaning in Hospitalisation'!$A$2:$A$2339,'DataCleaning in Hospitalisation'!$E$2:$E$2339) -> 5-Aug-1963 | M14: =_xlfn.XLOOKUP(A14,'DataCleaning in Hospitalisation'!$A$2:$A$2339,'DataCleaning in Hospitalisation'!$H$2:$H$2339) -> 47896.79 | N14: =_xlfn.XLOOKUP(A14,'DataCleaning in Hospitalisation'!$A$2:$A$2339,'DataCleaning in Hospitalisation'!$I$2:$I$2339) -> tier - 1 | O14: =_xlfn.XLOOKUP(A14,'DataCleaning in Hospitalisation'!$A$2:$A$2339,'DataCleaning in Hospitalisation'!$J$2:$J$2339) -> tier - 3 | P14: =_xlfn.XLOOKUP(A14,'DataCleaning in Hospitalisation'!$A$2:$A$2339,'DataCleaning in Hospitalisation'!$K$2:$K$2339) -> R1024 | Q14: =_xlfn.XLOOKUP(A14,'DataCleaning in Hospitalisation'!$A$2:$A$2339,'DataCleaning in Hospitalisation'!$F$2:$F$2339) -> 60 | U14: No | V14: 1 | X14: Id1008 | Y14: 11090.72 | AJ14: Id1008 | AK14: 11090.72
A15: Id14 | B15: =_xlfn.XLOOKUP(A15,'Customer Names'!$A$2:$A$2336,'Customer Names'!$C$2:$C$2336) -> Mr.Franklin | C15: =_xlfn.XLOOKUP(A15,'Data Cleaning in Medical Examin'!$A$2:$A$2336,'Data Cleaning in Medical Examin'!$B$2:$B$2336) -> 40.565 | D15: =_xlfn.XLOOKUP(A15,'Data Cleaning in Medical Examin'!$A$2:$A$2336,'Data Cleaning in Medical Examin'!$D$2:$D$2336) -> 7.02 | E15: =_xlfn.XLOOKUP(A15,'Data Cleaning in Medical Examin'!$A$2:$A$2336,'Data Cleaning in Medical Examin'!$F$2:$F$2336) -> No | F15: =_xlfn.XLOOKUP(A15,'Data Cleaning in Medical Examin'!$A$2:$A$2336,'Data Cleaning in Medical Examin'!$G$2:$G$2336) -> No | G15: =_xlfn.XLOOKUP(A15,'Data Cleaning in Medical Examin'!$A$2:$A$2336,'Data Cleaning in Medical Examin'!$H$2:$H$2336) -> No | H15: =_xlfn.XLOOKUP(A15,'Data Cleaning in Medical Examin'!$A$2:$A$2336,'Data Cleaning in Medical Examin'!$I$2:$I$2336) -> No Major Surgery | I15: =_xlfn.XLOOKUP(A15,'Data Cleaning in Medical Examin'!$A$2:$A$2336,'Data Cleaning in Medical Examin'!$J$2:$J$2336) -> Yes | J15: =_xlfn.XLOOKUP(A15,'Data Cleaning in Medical Examin'!$A$2:$A$2336,'Data Cleaning in Medical Examin'!$C$2:$C$2336) -> Obesity | K15: =_xlfn.XLOOKUP(A15,'Data Cleaning in Medical Examin'!$A$2:$A$2336,'Data Cleaning in Medical Examin'!$E$2:$E$2336) -> Diabetes | L15: =_xlfn.XLOOKUP(A15,'DataCleaning in Hospitalisation'!$A$2:$A$2339,'DataCleaning in Hospitalisation'!$E$2:$E$2339) -> 7-Nov-1964 | M15: =_xlfn.XLOOKUP(A15,'DataCleaning in Hospitalisation'!$A$2:$A$2339,'DataCleaning in Hospitalisation'!$H$2:$H$2339) -> 47496.49 | N15: =_xlfn.XLOOKUP(A15,'DataCleaning in Hospitalisation'!$A$2:$A$2339,'DataCleaning in Hospitalisation'!$I$2:$I$2339) -> tier - 1 | O15: =_xlfn.XLOOKUP(A15,'DataCleaning in Hospitalisation'!$A$2:$A$2339,'DataCleaning in Hospitalisation'!$J$2:$J$2339) -> tier - 3 | P15: =_xlfn.XLOOKUP(A15,'DataCleaning in Hospitalisation'!$A$2:$A$2339,'DataCleaning in Hospitalisation'!$K$2:$K$2339) -> R1012 | Q15: =_xlfn.XLOOKUP(A15,'DataCleaning in Hospitalisation'!$A$2:$A$2339,'DataCleaning in Hospitalisation'!$F$2:$F$2339) -> 59 | U15: Id100 | V15: 1 | X15: Id1009 | Y15: 11085.59 | AJ15: Id1009 | AK15: 11085.59
A16: Id15 | B16: =_xlfn.XLOOKUP(A16,'Customer Names'!$A$2:$A$2336,'Customer Names'!$C$2:$C$2336) -> Ms.Leilani | C16: =_xlfn.XLOOKUP(A16,'Data Cleaning in Medical Examin'!$A$2:$A$2336,'Data Cleaning in Medical Examin'!$B$2:$B$2336) -> 36.385 | D16: =_xlfn.XLOOKUP(A16,'Data Cleaning in Medical Examin'!$A$2:$A$2336,'Data Cleaning in Medical Examin'!$D$2:$D$2336) -> 7.59 | E16: =_xlfn.XLOOKUP(A16,'Data Cleaning in Medical Examin'!$A$2:$A$2336,'Data Cleaning in Medical Examin'!$F$2:$F$2336) -> Yes | F16: =_xlfn.XLOOKUP(A16,'Data Cleaning in Medical Examin'!$A$2:$A$2336,'Data Cleaning in Medical Examin'!$G$2:$G$2336) -> No | G16: =_xlfn.XLOOKUP(A16,'Data Cleaning in Medical Examin'!$A$2:$A$2336,'Data Cleaning in Medical Examin'!$H$2:$H$2336) -> No | H16: =_xlfn.XLOOKUP(A16,'Data Cleaning in Medical Examin'!$A$2:$A$2336,'Data Cleaning in Medical Examin'!$I$2:$I$2336) -> 2 Major Surgery | I16: =_xlfn.XLOOKUP(A16,'Data Cleaning in Medical Examin'!$A$2:$A$2336,'Data Cleaning in Medical Examin'!$J$2:$J$2336) -> Yes | J16: =_xlfn.XLOOKUP(A16,'Data Cleaning in Medical Examin'!$A$2:$A$2336,'Data Cleaning in Medical Examin'!$C$2:$C$2336) -> Obesity | K16: =_xlfn.XLOOKUP(A16,'Data Cleaning in Medical Examin'!$A$2:$A$2336,'Data Cleaning in Medical Examin'!$E$2:$E$2336) -> Diabetes | L16: =_xlfn.XLOOKUP(A16,'DataCleaning in Hospitalisation'!$A$2:$A$2339,'DataCleaning in Hospitalisation'!$E$2:$E$2339) -> 27-Sep-1971 | M16: =_xlfn.XLOOKUP(A16,'DataCleaning in Hospitalisation'!$A$2:$A$2339,'DataCleaning in Hospitalisation'!$H$2:$H$2339) -> 47462.89 | N16: =_xlfn.XLOOKUP(A16,'DataCleaning in Hospitalisation'!$A$2:$A$2339,'DataCleaning in Hospitalisation'!$I$2:$I$2339) -> tier - 1 | O16: =_xlfn.XLOOKUP(A16,'DataCleaning in Hospitalisation'!$A$2:$A$2339,'DataCleaning in Hospitalisation'!$J$2:$J$2339) -> tier - 2 | P16: =_xlfn.XLOOKUP(A16,'DataCleaning in Hospitalisation'!$A$2:$A$2339,'DataCleaning in Hospitalisation'!$K$2:$K$2339) -> R1013 | Q16: =_xlfn.XLOOKUP(A16,'DataCleaning in Hospitalisation'!$A$2:$A$2339,'DataCleaning in Hospitalisation'!$F$2:$F$2339) -> 52 | U16: tier - 1 | V16: 1 | X16: Id101 | Y16: 40069.44 | AJ16: Id101 | AK16: 40069.44
A17: Id16 | B17: =_xlfn.XLOOKUP(A17,'Customer Names'!$A$2:$A$2336,'Customer Names'!$C$2:$C$2336) -> Mr.Philippe | C17: =_xlfn.XLOOKUP(A17,'Data Cleaning in Medical Examin'!$A$2:$A$2336,'Data Cleaning in Medical Examin'!$B$2:$B$2336) -> 39.9 | D17: =_xlfn.XLOOKUP(A17,'Data Cleaning in Medical Examin'!$A$2:$A$2336,'Data Cleaning in Medical Examin'!$D$2:$D$2336) -> 11.32 | E17: =_xlfn.XLOOKUP(A17,'Data Cleaning in Medical Examin'!$A$2:$A$2336,'Data Cleaning in Medical Examin'!$F$2:$F$2336) -> No | F17: =_xlfn.XLOOKUP(A17,'Data Cleaning in Medical Examin'!$A$2:$A$2336,'Data Cleaning in Medical Examin'!$G$2:$G$2336) -> No | G17: =_xlfn.XLOOKUP(A17,'Data Cleaning in Medical Examin'!$A$2:$A$2336,'Data Cleaning in Medical Examin'!$H$2:$H$2336) -> No | H17: =_xlfn.XLOOKUP(A17,'Data Cleaning in Medical Examin'!$A$2:$A$2336,'Data Cleaning in Medical Examin'!$I$2:$I$2336) -> No Major Surgery | I17: =_xlfn.XLOOKUP(A17,'Data Cleaning in Medical Examin'!$A$2:$A$2336,'Data Cleaning in Medical Examin'!$J$2:$J$2336) -> Yes | J17: =_xlfn.XLOOKUP(A17,'Data Cleaning in Medical Examin'!$A$2:$A$2336,'Data Cleaning in Medical Examin'!$C$2:$C$2336) -> Obesity | K17: =_xlfn.XLOOKUP(A17,'Data Cleaning in Medical Examin'!$A$2:$A$2336,'Data Cleaning in Medical Examin'!$E$2:$E$2336) -> Diabetes | L17: =_xlfn.XLOOKUP(A17,'DataCleaning in Hospitalisation'!$A$2:$A$2339,'DataCleaning in Hospitalisation'!$E$2:$E$2339) -> 13-Jun-1961 | M17: =_xlfn.XLOOKUP(A17,'DataCleaning in Hospitalisation'!$A$2:$A$2339,'DataCleaning in Hospitalisation'!$H$2:$H$2339) -> 47403.88 | N17: =_xlfn.XLOOKUP(A17,'DataCleaning in Hospitalisation'!$A$2:$A$2339,'DataCleaning in Hospitalisation'!$I$2:$I$2339) -> tier - 1 | O17: =_xlfn.XLOOKUP(A17,'DataCleaning in Hospitalisation'!$A$2:$A$2339,'DataCleaning in Hospitalisation'!$J$2:$J$2339) -> tier - 3 | P17: =_xlfn.XLOOKUP(A17,'DataCleaning in Hospitalisation'!$A$2:$A$2339,'DataCleaning in Hospitalisation'!$K$2:$K$2339) -> R1011 | Q17: =_xlfn.XLOOKUP(A17,'DataCleaning in Hospitalisation'!$A$2:$A$2339,'DataCleaning in Hospitalisation'!$F$2:$F$2339) -> 62 | U17: No Major Surgery | V17: 1 | X17: Id1010 | Y17: 11082.58 | AJ17: Id1010 | AK17: 11082.58
A18: Id17 | B18: =_xlfn.XLOOKUP(A18,'Customer Names'!$A$2:$A$2336,'Customer Names'!$C$2:$C$2336) -> Ms.Jennifer | C18: =_xlfn.XLOOKUP(A18,'Data Cleaning in Medical Examin'!$A$2:$A$2336,'Data Cleaning in Medical Examin'!$B$2:$B$2336) -> 33.8 | D18: =_xlfn.XLOOKUP(A18,'Data Cleaning in Medical Examin'!$A$2:$A$2336,'Data Cleaning in Medical Examin'!$D$2:$D$2336) -> 7.67 | E18: =_xlfn.XLOOKUP(A18,'Data Cleaning in Medical Examin'!$A$2:$A$2336,'Data Cleaning in Medical Examin'!$F$2:$F$2336) -> No | F18: =_xlfn.XLOOKUP(A18,'Data Cleaning in Medical Examin'!$A$2:$A$2336,'Data Cleaning in Medical Examin'!$G$2:$G$2336) -> No | G18: =_xlfn.XLOOKUP(A18,'Data Cleaning in Medical Examin'!$A$2:$A$2336,'Data Cleaning in Medical Examin'!$H$2:$H$2336) -> No | H18: =_xlfn.XLOOKUP(A18,'Data Cleaning in Medical Examin'!$A$2:$A$2336,'Data Cleaning in Medical Examin'!$I$2:$I$2336) -> 3 Major Surgery | I18: =_xlfn.XLOOKUP(A18,'Data Cleaning in Medical Examin'!$A$2:$A$2336,'Data Cleaning in Medical Examin'!$J$2:$J$2336) -> Yes | J18: =_xlfn.XLOOKUP(A18,'Data Cleaning in Medical Examin'!$A$2:$A$2336,'Data Cleaning in Medical Examin'!$C$2:$C$2336) -> Obesity | K18: =_xlfn.XLOOKUP(A18,'Data Cleaning in Medical Examin'!$A$2:$A$2336,'Data Cleaning in Medical Examin'!$E$2:$E$2336) -> Diabetes | L18: =_xlfn.XLOOKUP(A18,'DataCleaning in Hospitalisation'!$A$2:$A$2339,'DataCleaning in Hospitalisation'!$E$2:$E$2339) -> 4-Oct-1959 | M18: =_xlfn.XLOOKUP(A18,'DataCleaning in Hospitalisation'!$A$2:$A$2339,'DataCleaning in Hospitalisation'!$H$2:$H$2339) -> 47305.31 | N18: =_xlfn.XLOOKUP(A18,'DataCleaning in Hospitalisation'!$A$2:$A$2339,'DataCleaning in Hospitalisation'!$I$2:$I$2339) -> tier - 2 | O18: =_xlfn.XLOOKUP(A18,'DataCleaning in Hospitalisation'!$A$2:$A$2339,'DataCleaning in Hospitalisation'!$J$2:$J$2339) -> tier - 1 | P18: =_xlfn.XLOOKUP(A18,'DataCleaning in Hospitalisation'!$A$2:$A$2339,'DataCleaning in Hospitalisation'!$K$2:$K$2339) -> R1011 | Q18: =_xlfn.XLOOKUP(A18,'DataCleaning in Hospitalisation'!$A$2:$A$2339,'DataCleaning in Hospitalisation'!$F$2:$F$2339) -> 64 | U18: tier - 2 | V18: 1 | X18: Id1011 | Y18: 11073.18 | AJ18: Id1011 | AK18: 11073.18
